<?xml version='1.0' encoding='utf-8'?>
<robot name="m0609_rg2">
  <link name="base_link">
    <inertial>
      <mass value="3.18" />
      <origin xyz="-2.8e-05   -0.006045    0.038403" />
      <inertia ixx="0.017789" ixy="-7.4356e-06" ixz="3.0378e-06" iyy="0.011135" iyz="-0.00029038" izz="0.020054" />
    </inertial>
    <visual>
      <origin rpy="0 0 0" xyz="0 0 0" />
      <geometry>
        <mesh filename="meshes/m0609/MF0609_0_0.dae" scale="0.001 0.001 0.001" />
      </geometry>
    </visual>
  </link>
  <link name="base" />
  <joint name="base_link-base" type="fixed">
    <origin rpy="0 0 0" xyz="0 0 0.450" />
    <parent link="base_link" />
    <child link="base" />
  </joint>
  
  <joint name="joint_1" type="revolute">
    <parent link="base_link" />
    <child link="link_1" />
    <origin rpy="0 0 0" xyz="0 0 0.1345" />
    <axis xyz="0 0 1" />
    <limit effort="163" lower="-6.2832" upper="6.2832" velocity="2.618" />
    <dynamics friction="0" />
  </joint>
  <link name="link_1">
    <inertial>
      <mass value="5.02" />
      <origin xyz="7.2e-05    0.036227   -0.003417" />
      <inertia ixx="0.026195" ixy="2.3904e-05" ixz="-1.3319e-05" iyy="0.016899" iyz="-0.00071987" izz="0.022944" />
    </inertial>
    <visual>
      <origin rpy="0 0 0" xyz="0 0 0" />
      <geometry>
        <mesh filename="meshes/m0609/MF0609_1_0.dae" scale="0.001 0.001 0.001" />
      </geometry>
    </visual>
  </link>
  
  <joint name="joint_2" type="revolute">
    <parent link="link_1" />
    <child link="link_2" />
    <origin rpy="0 -1.571 -1.571" xyz="0 0.0062 0" />
    <axis xyz="0 0 1" />
    <limit effort="163" lower="-6.2832" upper="6.2832" velocity="2.618" />
    <dynamics friction="0" />
  </joint>
  <link name="link_2">
    <inertial>
      <mass value="8.04" />
      <origin xyz="0.20447     2.6e-05     0.16005" />
      <inertia ixx="0.026743" ixy="-0.00019461" ixz="-0.00058734" iyy="0.30084" iyz="-6.7892e-06" izz="0.29898" />
    </inertial>
    <visual>
      <origin rpy="0 0 0" xyz="0 0 0" />
      <geometry>
        <mesh filename="meshes/m0609/MF0609_2_0.dae" scale="0.001 0.001 0.001" />
      </geometry>
    </visual>
    <visual>
      <origin rpy="0 0 0" xyz="0 0 0" />
      <geometry>
        <mesh filename="meshes/m0609/MF0609_2_1.dae" scale="0.001 0.001 0.001" />
      </geometry>
    </visual>
    <visual>
      <origin rpy="0 0 0" xyz="0 0 0" />
      <geometry>
        <mesh filename="meshes/m0609/MF0609_2_2.dae" scale="0.001 0.001 0.001" />
      </geometry>
    </visual>
  </link>
  
  <joint name="joint_3" type="revolute">
    <parent link="link_2" />
    <child link="link_3" />
    <origin rpy="0 0 1.571" xyz="0.411 0 0" />
    <axis xyz="0 0 1" />
    <limit effort="96" lower="-2.618" upper="2.618" velocity="3.1416" />
    <dynamics friction="0" />
  </joint>
  <link name="link_3">
    <inertial>
      <mass value="3.6" />
      <origin xyz="-2.2e-05   -0.006867    0.043445" />
      <inertia ixx="0.018342" ixy="1.1302e-05" ixz="-4.5308e-06" iyy="0.018239" iyz="-0.00099247" izz="0.01326" />
    </inertial>
    <visual>
      <origin rpy="0 0 0" xyz="0 0 0" />
      <geometry>
        <mesh filename="meshes/m0609/MF0609_3_0.dae" scale="0.001 0.001 0.001" />
      </geometry>
    </visual>
  </link>
  
  <joint name="joint_4" type="revolute">
    <parent link="link_3" />
    <child link="link_4" />
    <origin rpy="1.571 0 0" xyz="0 -0.368 0" />
    <axis xyz="0 0 1" />
    <limit effort="50" lower="-6.2832" upper="6.2832" velocity="3.927" />
    <dynamics friction="0" />
  </joint>
  <link name="link_4">
    <inertial>
      <mass value="3.57" />
      <origin xyz="4e-05    0.097079    -0.10981" />
      <inertia ixx="0.08035" ixy="-4.6119e-06" ixz="-8.1798e-06" iyy="0.066005" iyz="-0.028996" izz="0.029763" />
    </inertial>
    <visual>
      <origin rpy="0 0 0" xyz="0 0 0" />
      <geometry>
        <mesh filename="meshes/m0609/MF0609_4_0.dae" scale="0.001 0.001 0.001" />
      </geometry>
    </visual>
    <visual>
      <origin rpy="0 0 0" xyz="0 0 0" />
      <geometry>
        <mesh filename="meshes/m0609/MF0609_4_1.dae" scale="0.001 0.001 0.001" />
      </geometry>
    </visual>
  </link>
  
  <joint name="joint_5" type="revolute">
    <parent link="link_4" />
    <child link="link_5" />
    <origin rpy="-1.571 0 0" xyz="0 0 0" />
    <axis xyz="0 0 1" />
    <limit effort="50" lower="-6.2832" upper="6.2832" velocity="3.927" />
    <dynamics friction="0" />
  </joint>
  <link name="link_5">
    <inertial>
      <mass value="2.83" />
      <origin xyz="-6.8e-05    0.003827    0.031969" />
      <inertia ixx="0.014275" ixy="2.2026e-05" ixz="3.3017e-06" iyy="0.012569" iyz="0.00045077" izz="0.0085318" />
    </inertial>
    <visual>
      <origin rpy="0 0 0" xyz="0 0 0" />
      <geometry>
        <mesh filename="meshes/m0609/MF0609_5_0.dae" scale="0.001 0.001 0.001" />
      </geometry>
    </visual>
  </link>
  
  <joint name="joint_6" type="revolute">
    <parent link="link_5" />
    <child link="link_6" />
    <origin rpy="1.571 0 0" xyz="0 -0.121 0" />
    <axis xyz="0 0 1" />
    <limit effort="50" lower="-6.2832" upper="6.2832" velocity="3.927" />
    <dynamics friction="0" />
  </joint>
  <link name="link_6">
    <inertial>
      <mass value="1.16" />
      <origin xyz="-3e-05    -4.5e-05     -0.0539" />
      <inertia ixx="0.0080226" ixy="1.371e-06" ixz="6.3578e-06" iyy="0.0053992" iyz="7.4676e-06" izz="0.0053912" />
    </inertial>
    <visual>
      <origin rpy="0 0 0" xyz="0 0 0" />
      <geometry>
        <mesh filename="meshes/m0609/MF0609_6_0.dae" scale="0.001 0.001 0.001" />
      </geometry>
    </visual>
  </link>
  <link name="tool0" />
  <joint name="joint_6-tool0" type="fixed">
    <origin rpy="3.1415926535 -1.570796327 0" xyz="0 0 0" />
    <parent link="link_6" />
    <child link="tool0" />
  </joint>
  <link name="rg2_base_link">
    <inertial>
      <origin rpy="0 0 0" xyz="0.0 0.0 0.0" />
      <mass value="0.7" />
      <inertia ixx="1.0E-03" ixy="1.0E-06" ixz="1.0E-06" iyy="1.0E-03" iyz="1.0E-06" izz="1.0E-03" />
    </inertial>
    <visual>
      <origin rpy="0 0 0" xyz="0 0 0" />
      <geometry>
        <mesh filename="meshes/rg2/base_link.stl" />
      </geometry>
      <material name="">
        <color rgba="0.8 0.8 0.8 1" />
      </material>
    </visual>
    </link>
  <joint name="joint0" type="fixed">
    <parent link="tool0" />
    <child link="rg2_base_link" />
    <origin rpy="1.5708 0 1.5708" xyz="0. 0. 0." />
  </joint>
  <gazebo reference="rg2_base_link">
    <mu1>1.0</mu1>
    <mu2>1.0</mu2>
    <selfCollide>false</selfCollide>
    <material>Gazebo/White</material>
  </gazebo>
  <link name="rg2_left_outer_knuckle">
    <inertial>
      <origin rpy="0 0 0" xyz="0.0 0.0 0.0" />
      <mass value="0.05" />
      <inertia ixx="1.0E-03" ixy="1.0E-06" ixz="1.0E-06" iyy="1.0E-03" iyz="1.0E-06" izz="1.0E-03" />
    </inertial>
    <visual>
      <origin rpy="0 0 0" xyz="0 0 0" />
      <geometry>
        <mesh filename="meshes/rg2/outer_knuckle.stl" />
      </geometry>
      <material name="">
        <color rgba="0.8 0.8 0.8 1" />
      </material>
    </visual>
    </link>
  <gazebo reference="rg2_left_outer_knuckle">
    <mu1>0.1</mu1>
    <mu2>0.1</mu2>
    <selfCollide>false</selfCollide>
    <material>Gazebo/White</material>
  </gazebo>
  <link name="rg2_left_inner_knuckle">
    <inertial>
      <origin rpy="0 0 0" xyz="0.0 0.0 0.0" />
      <mass value="0.05" />
      <inertia ixx="1.0E-03" ixy="1.0E-06" ixz="1.0E-06" iyy="1.0E-03" iyz="1.0E-06" izz="1.0E-03" />
    </inertial>
    <visual>
      <origin rpy="0 0 0" xyz="0 0 0" />
      <geometry>
        <mesh filename="meshes/rg2/inner_knuckle.stl" />
      </geometry>
      <material name="">
        <color rgba="0.8 0.8 0.8 1" />
      </material>
    </visual>
    </link>
  <gazebo reference="rg2_left_inner_knuckle">
    <mu1>0.1</mu1>
    <mu2>0.1</mu2>
    <selfCollide>false</selfCollide>
    <material>Gazebo/White</material>
  </gazebo>
  <link name="rg2_left_inner_finger">
    <inertial>
      <origin rpy="0 0 0" xyz="0.0 0.0 0.0" />
      <mass value="0.05" />
      <inertia ixx="1.0E-03" ixy="1.0E-06" ixz="1.0E-06" iyy="1.0E-03" iyz="1.0E-06" izz="1.0E-03" />
    </inertial>
    <visual>
      <origin rpy="0 0 0" xyz="0 0 0" />
      <geometry>
        <mesh filename="meshes/rg2/inner_finger.stl" />
      </geometry>
      <material name="">
        <color rgba="0.1 0.1 0.1 1" />
      </material>
    </visual>
    </link>
  <gazebo reference="rg2_left_inner_finger">
    <kp>1000000.0</kp>
    <kd>1.0</kd>
    <mu1>1.0</mu1>
    <mu2>1.0</mu2>
    <minDepth>0.00001</minDepth>
    <selfCollide>false</selfCollide>
    <material>Gazebo/Black</material>
  </gazebo>
  <link name="rg2_right_outer_knuckle">
    <inertial>
      <origin rpy="0 0 0" xyz="0.0 0.0 0.0" />
      <mass value="0.05" />
      <inertia ixx="1.0E-03" ixy="1.0E-06" ixz="1.0E-06" iyy="1.0E-03" iyz="1.0E-06" izz="1.0E-03" />
    </inertial>
    <visual>
      <origin rpy="0 0 0" xyz="0 0 0" />
      <geometry>
        <mesh filename="meshes/rg2/outer_knuckle.stl" />
      </geometry>
      <material name="">
        <color rgba="0.8 0.8 0.8 1" />
      </material>
    </visual>
    </link>
  <gazebo reference="rg2_right_outer_knuckle">
    <mu1>0.1</mu1>
    <mu2>0.1</mu2>
    <selfCollide>false</selfCollide>
    <material>Gazebo/White</material>
  </gazebo>
  <link name="rg2_right_inner_knuckle">
    <inertial>
      <origin rpy="0 0 0" xyz="0.0 0.0 0.0" />
      <mass value="0.05" />
      <inertia ixx="1.0E-03" ixy="1.0E-06" ixz="1.0E-06" iyy="1.0E-03" iyz="1.0E-06" izz="1.0E-03" />
    </inertial>
    <visual>
      <origin rpy="0 0 0" xyz="0 0 0" />
      <geometry>
        <mesh filename="meshes/rg2/inner_knuckle.stl" />
      </geometry>
      <material name="">
        <color rgba="0.8 0.8 0.8 1" />
      </material>
    </visual>
    </link>
  <gazebo reference="rg2_right_inner_knuckle">
    <mu1>0.1</mu1>
    <mu2>0.1</mu2>
    <selfCollide>false</selfCollide>
    <material>Gazebo/White</material>
  </gazebo>
  <link name="rg2_right_inner_finger">
    <inertial>
      <origin rpy="0 0 0" xyz="0.0 0.0 0.0" />
      <mass value="0.05" />
      <inertia ixx="1.0E-03" ixy="1.0E-06" ixz="1.0E-06" iyy="1.0E-03" iyz="1.0E-06" izz="1.0E-03" />
    </inertial>
    <visual>
      <origin rpy="0 0 0" xyz="0 0 0" />
      <geometry>
        <mesh filename="meshes/rg2/inner_finger.stl" />
      </geometry>
      <material name="">
        <color rgba="0.1 0.1 0.1 1" />
      </material>
    </visual>
    </link>
  <gazebo reference="rg2_right_inner_finger">
    <kp>1000000.0</kp>
    <kd>1.0</kd>
    <mu1>1.0</mu1>
    <mu2>1.0</mu2>
    <minDepth>0.00001</minDepth>
    <selfCollide>false</selfCollide>
    <material>Gazebo/Black</material>
  </gazebo>
  <joint name="rg2_finger_joint" type="revolute">
    <origin rpy="0 0 0" xyz="0 -0.017178 0.125797" />
    <parent link="rg2_base_link" />
    <child link="rg2_left_outer_knuckle" />
    <axis xyz="-1 0 0" />
    <limit effort="1000" lower="-0.558505" upper="0.785398" velocity="100.0" />
  </joint>
  <joint name="rg2_left_inner_knuckle_joint" type="revolute">
    <origin rpy="0 0 0.0" xyz="0 -0.007678 0.1422970" />
    <parent link="rg2_base_link" />
    <child link="rg2_left_inner_knuckle" />
    <axis xyz="1 0 0" />
    <limit effort="1000" lower="-0.785398" upper="0.785398" velocity="100.0" />
    <mimic joint="rg2_finger_joint" multiplier="-1" offset="0" />
  </joint>
  <joint name="rg2_left_inner_finger_joint" type="revolute">
    <origin rpy="0 0 0" xyz="0 -0.039592 0.038177000000000016" />
    <parent link="rg2_left_outer_knuckle" />
    <child link="rg2_left_inner_finger" />
    <axis xyz="1 0 0" />
    <limit effort="1000" lower="-0.872665" upper="0.872665" velocity="100.0" />
    <mimic joint="rg2_finger_joint" multiplier="1" offset="0" />
  </joint>
  <joint name="rg2_right_outer_knuckle_joint" type="revolute">
    <parent link="rg2_base_link" />
    <child link="rg2_right_outer_knuckle" />
    <origin rpy="0 0 3.141592653589793" xyz="0 0.017178 0.125797" />
    <axis xyz="1 0 0" />
    <limit effort="1000" lower="-0.785398" upper="0.785398" velocity="100.0" />
    <mimic joint="rg2_finger_joint" multiplier="-1" offset="0" />
  </joint>
  <joint name="rg2_right_inner_knuckle_joint" type="revolute">
    <origin rpy="0 0 -3.141592653589793" xyz="0 0.007678 0.1422970" />
    <parent link="rg2_base_link" />
    <child link="rg2_right_inner_knuckle" />
    <axis xyz="1 0 0" />
    <limit effort="1000" lower="-0.785398" upper="0.785398" velocity="100.0" />
    <mimic joint="rg2_finger_joint" multiplier="-1" offset="0" />
  </joint>
  <joint name="rg2_right_inner_finger_joint" type="revolute">
    <origin rpy="0 0 0" xyz="0 -0.039592 0.038177000000000016" />
    <parent link="rg2_right_outer_knuckle" />
    <child link="rg2_right_inner_finger" />
    <axis xyz="1 0 0" />
    <limit effort="1000" lower="-0.872665" upper="0.872665" velocity="100.0" />
    <mimic joint="rg2_finger_joint" multiplier="1" offset="0" />
  </joint>
  <transmission name="rg2_finger_joint_trans">
    <type>transmission_interface/SimpleTransmission</type>
    <joint name="rg2_finger_joint">
      <hardwareInterface>hardware_interface/EffortJointInterface</hardwareInterface>
    </joint>
    <actuator name="rg2_finger_joint_motor">
      <hardwareInterface>hardware_interface/EffortJointInterface</hardwareInterface>
      <mechanicalReduction>1</mechanicalReduction>
    </actuator>
  </transmission>
  <gazebo>
    <plugin filename="libgazebo_ros2_control.so" name="gazebo_ros2_control">
      <robotNamespace>/onrobot_rg2</robotNamespace>
      <robotSimType>gazebo_ros2_control/DefaultRobotHWSim</robotSimType>
    </plugin>
  </gazebo>
  <gazebo>
    <plugin filename="libroboticsgroup_upatras_gazebo_mimic_joint_plugin.so" name="mimic_rg2_left_inner_knuckle_joint">
      <joint>rg2_finger_joint</joint>
      <mimicJoint>rg2_left_inner_knuckle_joint</mimicJoint>
      <multiplier>-1.0</multiplier>
      <offset>0.0</offset>
      <maxEffort>5.0</maxEffort>
      
    </plugin>
    <plugin filename="libroboticsgroup_upatras_gazebo_mimic_joint_plugin.so" name="mimic_rg2_right_inner_knuckle_joint">
      <joint>rg2_finger_joint</joint>
      <mimicJoint>rg2_right_inner_knuckle_joint</mimicJoint>
      <multiplier>-1.0</multiplier>
      <offset>0.0</offset>
      <maxEffort>5.0</maxEffort>
      
    </plugin>
    <plugin filename="libroboticsgroup_upatras_gazebo_mimic_joint_plugin.so" name="mimic_rg2_left_inner_finger_joint">
      <joint>rg2_finger_joint</joint>
      <mimicJoint>rg2_left_inner_finger_joint</mimicJoint>
      <multiplier>1.0</multiplier>
      <offset>0.0</offset>
      <maxEffort>5.0</maxEffort>
      
    </plugin>
    <plugin filename="libroboticsgroup_upatras_gazebo_mimic_joint_plugin.so" name="mimic_rg2_right_inner_finger_joint">
      <joint>rg2_finger_joint</joint>
      <mimicJoint>rg2_right_inner_finger_joint</mimicJoint>
      <multiplier>1.0</multiplier>
      <offset>0.0</offset>
      <maxEffort>5.0</maxEffort>
      
    </plugin>
    <plugin filename="libroboticsgroup_upatras_gazebo_mimic_joint_plugin.so" name="mimic_rg2_right_outer_knuckle_joint">
      <joint>rg2_finger_joint</joint>
      <mimicJoint>rg2_right_outer_knuckle_joint</mimicJoint>
      <multiplier>-1.0</multiplier>
      <offset>0.0</offset>
      <maxEffort>5.0</maxEffort>
      
    </plugin>
  </gazebo>
</robot>